test_runner/resources/scripts/scenario-2.txt
# Action
BUY   100@25.00
BUY    99@25.00
BUY    33@25.00
BUY   200@26.00
BUY  1000@00.01
BUY   199@26.00
BUY    33@25.00
BUY   100@24.00
SELL  100@30.00  #C
SELL  200@30.00  #D
SELL  100@31.00  #E
SELL  400@29.00  #A
SELL  100@29.00  #B
SELL  100@31.00  #F
SELL 1000@2000.00 #G
SELL   50@26.00
SELL  400@25.00
BUY   199@29.00
CANCEL #B
CANCEL #A
CANCEL #C
CANCEL #D
CANCEL #E
CANCEL #F
CANCEL #G
SELL  100@30.00
SELL  200@30.00
SELL  100@31.00
SELL  400@29.00
SELL  100@29.00
SELL  100@31.00
